<?xml version="1.0" encoding="UTF-8"?>
<!-- Generated by org.testng.reporters.JUnitReportReporter -->
<testsuite hostname="DESKTOP-1UFPC69" failures="3" tests="8" name="com.vtiger.practice.TestNgAssert" time="0.028" errors="0" timestamp="2022-05-23T12:42:35 IST" skipped="5">
  <testcase classname="com.vtiger.practice.TestNgAssert" name="practice1" time="0.002">
    <skipped/>
  </testcase> <!-- practice1 -->
  <system-out>
    <![CDATA[pass1]]>
  </system-out>
  <testcase classname="com.vtiger.practice.TestNgAssert" name="practice1" time="0.001">
    <failure message="expected [123] but found [abc]" type="java.lang.AssertionError">
      <![CDATA[java.lang.AssertionError: expected [123] but found [abc]
at org.testng.Assert.fail(Assert.java:99)
at org.testng.Assert.failNotEquals(Assert.java:1037)
at org.testng.Assert.assertEqualsImpl(Assert.java:140)
at org.testng.Assert.assertEquals(Assert.java:122)
at org.testng.Assert.assertEquals(Assert.java:629)
at org.testng.Assert.assertEquals(Assert.java:639)
at com.vtiger.practice.TestNgAssert.practice1(TestNgAssert.java:14)
at java.base/jdk.internal.reflect.NativeMethodAccessorImpl.invoke0(Native Method)
at java.base/jdk.internal.reflect.NativeMethodAccessorImpl.invoke(NativeMethodAccessorImpl.java:78)
at java.base/jdk.internal.reflect.DelegatingMethodAccessorImpl.invoke(DelegatingMethodAccessorImpl.java:43)
at java.base/java.lang.reflect.Method.invoke(Method.java:567)
at org.testng.internal.MethodInvocationHelper.invokeMethod(MethodInvocationHelper.java:133)
at org.testng.internal.TestInvoker.invokeMethod(TestInvoker.java:598)
at org.testng.internal.TestInvoker.retryFailed(TestInvoker.java:213)
at org.testng.internal.MethodRunner.runInSequence(MethodRunner.java:58)
at org.testng.internal.TestInvoker$MethodInvocationAgent.invoke(TestInvoker.java:824)
at org.testng.internal.TestInvoker.invokeTestMethods(TestInvoker.java:146)
at org.testng.internal.TestMethodWorker.invokeTestMethods(TestMethodWorker.java:146)
at org.testng.internal.TestMethodWorker.run(TestMethodWorker.java:128)
at java.base/java.util.concurrent.ThreadPoolExecutor.runWorker(ThreadPoolExecutor.java:1130)
at java.base/java.util.concurrent.ThreadPoolExecutor$Worker.run(ThreadPoolExecutor.java:630)
at java.base/java.lang.Thread.run(Thread.java:831)
]]>
    </failure>
  </testcase> <!-- practice1 -->
  <system-out>
    <![CDATA[pass1]]>
  </system-out>
  <testcase classname="com.vtiger.practice.TestNgAssert" name="practice1" time="0.017">
    <skipped/>
  </testcase> <!-- practice1 -->
  <system-out>
    <![CDATA[pass1]]>
  </system-out>
  <testcase classname="com.vtiger.practice.TestNgAssert" name="practice3" time="0.002">
    <failure message="expected [789] but found [hij]" type="java.lang.AssertionError">
      <![CDATA[java.lang.AssertionError: expected [789] but found [hij]
at org.testng.Assert.fail(Assert.java:99)
at org.testng.Assert.failNotEquals(Assert.java:1037)
at org.testng.Assert.assertEqualsImpl(Assert.java:140)
at org.testng.Assert.assertEquals(Assert.java:122)
at org.testng.Assert.assertEquals(Assert.java:629)
at org.testng.Assert.assertEquals(Assert.java:639)
at com.vtiger.practice.TestNgAssert.practice3(TestNgAssert.java:24)
at java.base/jdk.internal.reflect.NativeMethodAccessorImpl.invoke0(Native Method)
at java.base/jdk.internal.reflect.NativeMethodAccessorImpl.invoke(NativeMethodAccessorImpl.java:78)
at java.base/jdk.internal.reflect.DelegatingMethodAccessorImpl.invoke(DelegatingMethodAccessorImpl.java:43)
at java.base/java.lang.reflect.Method.invoke(Method.java:567)
at org.testng.internal.MethodInvocationHelper.invokeMethod(MethodInvocationHelper.java:133)
at org.testng.internal.TestInvoker.invokeMethod(TestInvoker.java:598)
at org.testng.internal.TestInvoker.invokeTestMethod(TestInvoker.java:173)
at org.testng.internal.MethodRunner.runInSequence(MethodRunner.java:46)
at org.testng.internal.TestInvoker$MethodInvocationAgent.invoke(TestInvoker.java:824)
at org.testng.internal.TestInvoker.invokeTestMethods(TestInvoker.java:146)
at org.testng.internal.TestMethodWorker.invokeTestMethods(TestMethodWorker.java:146)
at org.testng.internal.TestMethodWorker.run(TestMethodWorker.java:128)
at java.base/java.util.concurrent.ThreadPoolExecutor.runWorker(ThreadPoolExecutor.java:1130)
at java.base/java.util.concurrent.ThreadPoolExecutor$Worker.run(ThreadPoolExecutor.java:630)
at java.base/java.lang.Thread.run(Thread.java:831)
]]>
    </failure>
  </testcase> <!-- practice3 -->
  <system-out>
    <![CDATA[pass3]]>
  </system-out>
  <testcase classname="com.vtiger.practice.TestNgAssert" name="practice2" time="0.000">
    <skipped/>
  </testcase> <!-- practice2 -->
  <system-out/>
  <testcase classname="com.vtiger.practice.TestNgAssert" name="practice1" time="0.001">
    <skipped/>
  </testcase> <!-- practice1 -->
  <system-out>
    <![CDATA[pass1]]>
  </system-out>
  <testcase classname="com.vtiger.practice.TestNgAssert" name="practice1" time="0.002">
    <skipped/>
  </testcase> <!-- practice1 -->
  <system-out>
    <![CDATA[pass1]]>
  </system-out>
  <testcase classname="com.vtiger.practice.TestNgAssert" name="practice3" time="0.003">
    <failure message="expected [789] but found [hij]" type="java.lang.AssertionError">
      <![CDATA[java.lang.AssertionError: expected [789] but found [hij]
at org.testng.Assert.fail(Assert.java:99)
at org.testng.Assert.failNotEquals(Assert.java:1037)
at org.testng.Assert.assertEqualsImpl(Assert.java:140)
at org.testng.Assert.assertEquals(Assert.java:122)
at org.testng.Assert.assertEquals(Assert.java:629)
at org.testng.Assert.assertEquals(Assert.java:639)
at com.vtiger.practice.TestNgAssert.practice3(TestNgAssert.java:24)
at java.base/jdk.internal.reflect.NativeMethodAccessorImpl.invoke0(Native Method)
at java.base/jdk.internal.reflect.NativeMethodAccessorImpl.invoke(NativeMethodAccessorImpl.java:78)
at java.base/jdk.internal.reflect.DelegatingMethodAccessorImpl.invoke(DelegatingMethodAccessorImpl.java:43)
at java.base/java.lang.reflect.Method.invoke(Method.java:567)
at org.testng.internal.MethodInvocationHelper.invokeMethod(MethodInvocationHelper.java:133)
at org.testng.internal.TestInvoker.invokeMethod(TestInvoker.java:598)
at org.testng.internal.TestInvoker.invokeTestMethod(TestInvoker.java:173)
at org.testng.internal.MethodRunner.runInSequence(MethodRunner.java:46)
at org.testng.internal.TestInvoker$MethodInvocationAgent.invoke(TestInvoker.java:824)
at org.testng.internal.TestInvoker.invokeTestMethods(TestInvoker.java:146)
at org.testng.internal.TestMethodWorker.invokeTestMethods(TestMethodWorker.java:146)
at org.testng.internal.TestMethodWorker.run(TestMethodWorker.java:128)
at java.base/java.util.concurrent.ThreadPoolExecutor.runWorker(ThreadPoolExecutor.java:1130)
at java.base/java.util.concurrent.ThreadPoolExecutor$Worker.run(ThreadPoolExecutor.java:630)
at java.base/java.lang.Thread.run(Thread.java:831)
]]>
    </failure>
  </testcase> <!-- practice3 -->
  <system-out>
    <![CDATA[pass3]]>
  </system-out>
</testsuite> <!-- com.vtiger.practice.TestNgAssert -->
